[2025-07-26T09:13:45.954+0000] {local_task_job_runner.py:120} INFO - ::group::Pre task execution logs
[2025-07-26T09:13:45.965+0000] {taskinstance.py:2076} INFO - Dependencies all met for dep_context=non-requeueable deps ti=<TaskInstance: preview_next_row_dag.preview_row manual__2025-07-26T09:13:44.631291+00:00 [queued]>
[2025-07-26T09:13:45.968+0000] {taskinstance.py:2076} INFO - Dependencies all met for dep_context=requeueable deps ti=<TaskInstance: preview_next_row_dag.preview_row manual__2025-07-26T09:13:44.631291+00:00 [queued]>
[2025-07-26T09:13:45.968+0000] {taskinstance.py:2306} INFO - Starting attempt 1 of 1
[2025-07-26T09:13:45.972+0000] {taskinstance.py:2330} INFO - Executing <Task(PythonOperator): preview_row> on 2025-07-26 09:13:44.631291+00:00
[2025-07-26T09:13:45.976+0000] {logging_mixin.py:188} WARNING - /home/***/.local/lib/python3.12/site-packages/***/task/task_runner/standard_task_runner.py:62 DeprecationWarning: This process (pid=235) is multi-threaded, use of fork() may lead to deadlocks in the child.
[2025-07-26T09:13:45.976+0000] {standard_task_runner.py:64} INFO - Started process 260 to run task
[2025-07-26T09:13:45.977+0000] {standard_task_runner.py:90} INFO - Running: ['***', 'tasks', 'run', 'preview_next_row_dag', 'preview_row', 'manual__2025-07-26T09:13:44.631291+00:00', '--job-id', '2', '--raw', '--subdir', 'DAGS_FOLDER/preview.py', '--cfg-path', '/tmp/tmp3a7cip8u']
[2025-07-26T09:13:45.977+0000] {standard_task_runner.py:91} INFO - Job 2: Subtask preview_row
[2025-07-26T09:13:45.983+0000] {logging_mixin.py:188} WARNING - /home/***/.local/lib/python3.12/site-packages/***/settings.py:195 DeprecationWarning: The sql_alchemy_conn option in [core] has been moved to the sql_alchemy_conn option in [database] - the old setting has been used, but please update your config.
[2025-07-26T09:13:45.999+0000] {task_command.py:426} INFO - Running <TaskInstance: preview_next_row_dag.preview_row manual__2025-07-26T09:13:44.631291+00:00 [running]> on host 2992d32593f0
[2025-07-26T09:13:46.076+0000] {taskinstance.py:2648} INFO - Exporting env vars: AIRFLOW_CTX_DAG_OWNER='***' AIRFLOW_CTX_DAG_ID='preview_next_row_dag' AIRFLOW_CTX_TASK_ID='preview_row' AIRFLOW_CTX_EXECUTION_DATE='2025-07-26T09:13:44.631291+00:00' AIRFLOW_CTX_TRY_NUMBER='1' AIRFLOW_CTX_DAG_RUN_ID='manual__2025-07-26T09:13:44.631291+00:00'
[2025-07-26T09:13:46.076+0000] {taskinstance.py:430} INFO - ::endgroup::
[2025-07-26T09:13:46.091+0000] {logging_mixin.py:188} INFO - Reading from: /opt/***/data/holdout.parquet
[2025-07-26T09:13:46.097+0000] {logging_mixin.py:188} INFO - Error in preview_next_row:
[2025-07-26T09:13:46.098+0000] {logging_mixin.py:188} WARNING - Traceback (most recent call last):
[2025-07-26T09:13:46.098+0000] {logging_mixin.py:188} WARNING -   File "/opt/***/dags/preview.py", line 12, in preview_next_row
    df = pd.read_parquet(parquet_path)
         ^^^^^^^^^^^^^^^^^^^^^^^^^^^^^
[2025-07-26T09:13:46.098+0000] {logging_mixin.py:188} WARNING -   File "/home/***/.local/lib/python3.12/site-packages/pandas/io/parquet.py", line 670, in read_parquet
    return impl.read(
           ^^^^^^^^^^
[2025-07-26T09:13:46.098+0000] {logging_mixin.py:188} WARNING -   File "/home/***/.local/lib/python3.12/site-packages/pandas/io/parquet.py", line 265, in read
    path_or_handle, handles, filesystem = _get_path_or_handle(
                                          ^^^^^^^^^^^^^^^^^^^^
[2025-07-26T09:13:46.098+0000] {logging_mixin.py:188} WARNING -   File "/home/***/.local/lib/python3.12/site-packages/pandas/io/parquet.py", line 139, in _get_path_or_handle
    handles = get_handle(
              ^^^^^^^^^^^
[2025-07-26T09:13:46.098+0000] {logging_mixin.py:188} WARNING -   File "/home/***/.local/lib/python3.12/site-packages/pandas/io/common.py", line 872, in get_handle
    handle = open(handle, ioargs.mode)
             ^^^^^^^^^^^^^^^^^^^^^^^^^
[2025-07-26T09:13:46.098+0000] {logging_mixin.py:188} WARNING - FileNotFoundError: [Errno 2] No such file or directory: '/opt/***/data/holdout.parquet'
[2025-07-26T09:13:46.098+0000] {taskinstance.py:441} INFO - ::group::Post task execution logs
[2025-07-26T09:13:46.098+0000] {taskinstance.py:2905} ERROR - Task failed with exception
Traceback (most recent call last):
  File "/home/airflow/.local/lib/python3.12/site-packages/airflow/models/taskinstance.py", line 465, in _execute_task
    result = _execute_callable(context=context, **execute_callable_kwargs)
             ^^^^^^^^^^^^^^^^^^^^^^^^^^^^^^^^^^^^^^^^^^^^^^^^^^^^^^^^^^^^^
  File "/home/airflow/.local/lib/python3.12/site-packages/airflow/models/taskinstance.py", line 432, in _execute_callable
    return execute_callable(context=context, **execute_callable_kwargs)
           ^^^^^^^^^^^^^^^^^^^^^^^^^^^^^^^^^^^^^^^^^^^^^^^^^^^^^^^^^^^^
  File "/home/airflow/.local/lib/python3.12/site-packages/airflow/models/baseoperator.py", line 401, in wrapper
    return func(self, *args, **kwargs)
           ^^^^^^^^^^^^^^^^^^^^^^^^^^^
  File "/home/airflow/.local/lib/python3.12/site-packages/airflow/operators/python.py", line 235, in execute
    return_value = self.execute_callable()
                   ^^^^^^^^^^^^^^^^^^^^^^^
  File "/home/airflow/.local/lib/python3.12/site-packages/airflow/operators/python.py", line 252, in execute_callable
    return self.python_callable(*self.op_args, **self.op_kwargs)
           ^^^^^^^^^^^^^^^^^^^^^^^^^^^^^^^^^^^^^^^^^^^^^^^^^^^^^
  File "/opt/airflow/dags/preview.py", line 29, in preview_next_row
    raise e
  File "/opt/airflow/dags/preview.py", line 12, in preview_next_row
    df = pd.read_parquet(parquet_path)
         ^^^^^^^^^^^^^^^^^^^^^^^^^^^^^
  File "/home/airflow/.local/lib/python3.12/site-packages/pandas/io/parquet.py", line 670, in read_parquet
    return impl.read(
           ^^^^^^^^^^
  File "/home/airflow/.local/lib/python3.12/site-packages/pandas/io/parquet.py", line 265, in read
    path_or_handle, handles, filesystem = _get_path_or_handle(
                                          ^^^^^^^^^^^^^^^^^^^^
  File "/home/airflow/.local/lib/python3.12/site-packages/pandas/io/parquet.py", line 139, in _get_path_or_handle
    handles = get_handle(
              ^^^^^^^^^^^
  File "/home/airflow/.local/lib/python3.12/site-packages/pandas/io/common.py", line 872, in get_handle
    handle = open(handle, ioargs.mode)
             ^^^^^^^^^^^^^^^^^^^^^^^^^
FileNotFoundError: [Errno 2] No such file or directory: '/opt/airflow/data/holdout.parquet'
[2025-07-26T09:13:46.103+0000] {taskinstance.py:1206} INFO - Marking task as FAILED. dag_id=preview_next_row_dag, task_id=preview_row, run_id=manual__2025-07-26T09:13:44.631291+00:00, execution_date=20250726T091344, start_date=20250726T091345, end_date=20250726T091346
[2025-07-26T09:13:46.107+0000] {standard_task_runner.py:110} ERROR - Failed to execute job 2 for task preview_row ([Errno 2] No such file or directory: '/opt/airflow/data/holdout.parquet'; 260)
[2025-07-26T09:13:46.149+0000] {local_task_job_runner.py:243} INFO - Task exited with return code 1
[2025-07-26T09:13:46.176+0000] {taskinstance.py:3503} INFO - 0 downstream tasks scheduled from follow-on schedule check
[2025-07-26T09:13:46.178+0000] {local_task_job_runner.py:222} INFO - ::endgroup::
